<mujoco model="hello">
  <option gravity="0 0 -9.81"/>


  <worldbody>
    <light pos="0 0 5" dir="0 0 -1" diffuse="0.3 0.3 0.3"/>
    <geom name="floor" size="0 0 0.05" rgba="1.0 0.0 0.0 1.0" type="plane"/>

     <body name="base" pos="0 0 0.6">
            <geom name="link0" type="box" size="0.1 0.2 0.6" rgba="0.0 1.0 1.0 1.0" pos="0 0 0"/>
            <inertial pos="0 0 0" mass="0.1" diaginertia="0 0 0"/>
 
            <!-- nest each child piece inside the parent body tags -->
            <body name="link1" pos="-0.1 0 1.2">
                <!-- this joint connects link1 to the base -->
                <joint name="joint0" type="hinge" axis="0 -1 0" pos="0.0 0.0 -0.6"/>
 
                <geom name="link1" type="box" size="0.1 0.2 0.6" rgba="0.0 1.0 0.0 1.0" pos="0 0 0" euler="0 3.14 0"/>
                <inertial pos="0 0 0" mass="0.1" diaginertia="1 1 1"/>
 
                <body name="link2" pos="0.05 0 1.2">
                    <!-- this joint connects link2 to link1 -->
                    <joint name="joint1" type="hinge" axis="0 -1 0" pos="0 0 -0.6"/>
 
                    <geom name="link2" type="box"  size="0.1 0.2 0.6" rgba="1.0 1.0 0.0 1.0" pos="0 0 0" euler="0 3.14 0"/>
                    <inertial pos="0 0 0" mass="0.1" diaginertia="1 1 1"/>
 
                    <!-- the ABR Control Mujoco interface uses the EE body to -->
                    <!-- identify the end-effector point to control with OSC-->
                    <body name="EE" pos="0 0.2 0.2">
                        <inertial pos="0 0 0" mass="0" diaginertia="0 0 0" />
                    </body>
                </body>
            </body>
        </body>
    </worldbody>
 
    <actuator>
        <motor name="joint0_motor" joint="joint0"/>
        <motor name="joint1_motor" joint="joint1"/>
    </actuator>


</mujoco>
