<mujoco model="Kayra">
  <option gravity="0 0 -9.81"/>
   <compiler angle="radian"/>

<default>
  <mesh scale="0.01 0.01 0.01"/>
  <geom type="mesh" solref="0.005 1"/>
  <position kp="21.1" ctrlrange="-3.141592 3.141592" forcerange="-5 5"/>
</default>

  <asset>
    <texture name="grid" type="2d" builtin="checker" width="512" height="512" rgb1=".1 .2 .3" rgb2=".2 .3 .4"/>
    <material name="blue" rgba="0.23 0.51 0.74 1"/>
    <material name="yellow" rgba="0.99 0.74 0.0 1"/>
    <material name="white" rgba="0.98 0.98 0.97 1"/>
    <material name="grid" texture="grid" texrepeat="1 1" texuniform="true" reflectance=".2"/>
    <mesh name="1R_foot" file="../STL/1R_foot-Body.stl"/>
    <mesh name="2R_footJoint" file="../STL/2R_footJoint_bearing-Body.stl"/>
    <mesh name="3BR_calf" file="../STL/3BR_calf-Body.stl"/>
    <mesh name="3FU_shin" file="../STL/3FU_shin-Body.stl"/>
    <mesh name="4R_knee" file="../STL/4R_knee-Body.stl"/>
	<mesh name="5R_hipjoint_lower" file="../STL/5R_hipjoint_lower-Body.stl"/>
    <mesh name="5R_hipjoint_upper" file="../STL/5R_hipjoint_upper_bearing-Body.stl"/>
  </asset>  

  <worldbody>
   <camera name="follow" pos="-2.0 2.0 3" xyaxes="-1.0 -1 0 1.0 0 1" mode="trackcom"/>
    <!-- light pos="0 0 1" dir="0 0 -1" diffuse="0.1 0.8 0.8"/-->
    <light directional="true" pos="-0.5 0.5 3" dir="0 0 -1" />
    <!-- geom name="floor" size="1 1 0.05" rgba="1.0 0.0 0.0 1.0" type="plane"/-->
    <!-- geom name="floor" pos="0 0 -0.1" size="0 0 0.1" type="plane" rgba="0.4 0.4 0.4 1.0"/-->
    <geom name="floor" size="0 0 .05" type="plane" material="grid" condim="3"/>

    <body name="4R_Link" pos="0 0 1.8" euler= "-0.0 0.0 0.0">
        <joint type="free"/>

        <inertial pos="0 0 0.1" mass="0.10" diaginertia="0.005 0.005 0.005"/>
        <geom mesh="4R_knee" type="mesh" material="white"/>

        <body name="3BR_Link" pos="0 -0.17 -0.225" euler="1.57 0 -1.57">
             <joint name="3BR_Joint" axis="0 1 0" pos="-0.10 0.0 0.14"/>

            <inertial pos="0 0 0" mass="0.10" diaginertia="0.005 0.005 0.005"/>
            <geom mesh="3BR_calf" type="mesh" euler="0 0 0" pos="0.0 0.0 0.0" material="white"/>

			<body name="2R_Link" pos="1.0 -0.3 0.2" euler= "0 -1.57 1.57">
				<joint name="2R_Joint" axis="1 0 0" pos="0.23 0.05 0.45"/>

				<inertial pos="0 0 0.1" mass="0.05" diaginertia="0.005 0.005 0.005"/>
				<geom mesh="2R_footJoint" type="mesh" material="yellow"/>

				<body name="3FU_Link" pos="0.3 0.35 0.62" euler="-1.57 0 0">
					<joint name="3FU_Joint" axis="1 0 0" pos="-0.03 0.3 -0.03"/>

					<inertial pos="0 0 0" mass="0.05" diaginertia="0.005 0.005 0.005"/>
					<geom mesh="3FU_shin" type="mesh" euler="0 0 0" pos="0.0 0.0 0.0" material="blue"/>
				</body> 

				<body name="1R_Link" pos="0.3 0.2 -0.15" euler="0 0 0.0">
					<joint name="1R_Joint" axis="0 1 0" pos="0.08 -0.03 0.27"/>
					<inertial pos="0 0 0" mass="0.05" diaginertia="0.005 0.005 0.005"/>
					<geom mesh="1R_foot" type="mesh" euler="0 0 0" pos="0.0 0.0 0.0" material="blue"/>
				</body> 
			</body>
        </body>
    </body>


<!--
    <body pos="0 0 2" euler= "0 0 0">
        <joint type="free"/>
        <inertial pos="0 0 0.1" mass="0.05" diaginertia="0.005 0.005 0.005"/>
        <geom mesh="2R_footJoint" type="mesh" material="yellow"/>
    </body>

    <body pos="0 0.0 1.5" euler= "0 0 0">
        <joint type="free"/>
        <inertial pos="0 0 0.1" mass="0.10" diaginertia="0.005 0.005 0.005"/>
        <geom mesh="3BR_calf" type="mesh" material="white"/>
    </body>

    <body pos="0 0 2.5" euler= "0 0 0">
        <joint type="free"/>
        <inertial pos="0 0 0.1" mass="0.05" diaginertia="0.005 0.005 0.005"/>
        <geom mesh="3FU_shin" type="mesh" material="blue"/>
    </body>

    <body pos="0 0 3.0" euler= "0 0 0">
        <joint type="free"/>
        <inertial pos="0 0 0.1" mass="0.05" diaginertia="0.005 0.005 0.005"/>
        <geom mesh="1R_foot" type="mesh" material="blue"/>
    </body>
-->
  </worldbody>

    <equality>
        <connect name="lowerRightLeg_kinematic_link" active="true" body1="4R_Link" body2="3FU_Link" anchor="0.25 -0.05 -0.26"/>
    </equality >

	<actuator>
		<position name="Right Calf 3BR" joint="3BR_Joint"/>
		<position name="Right Foot 1R" joint="1R_Joint"/>
	</actuator>

</mujoco>
